<?xml version="1.0" encoding="UTF-8"?>
<!-- Generated by org.testng.reporters.JUnitXMLReporter -->
<testsuite hostname="BDC6-DX-6G88NK2" ignored="0" name="Test" tests="4" failures="2" timestamp="17 Sep 2019 10:10:06 GMT" time="0.056" errors="0">
  <testcase name="testmethod" time="0.016" classname="Day1.softassert">
    <failure type="java.lang.AssertionError" message="The following asserts failed:
	expected [11] but found [10],
	expected [Welcome] but found [Hello]">
      <![CDATA[java.lang.AssertionError: The following asserts failed:
expected [11] but found [10],
expected [Welcome] but found [Hello]
at Day1.softassert.testmethod(softassert.java:14)
at java.util.concurrent.FutureTask.run(Unknown Source)
at java.util.concurrent.ThreadPoolExecutor.runWorker(Unknown Source)
at java.util.concurrent.ThreadPoolExecutor$Worker.run(Unknown Source)
at java.lang.Thread.run(Unknown Source)
... Removed 17 stack frames]]>
    </failure>
  </testcase> <!-- testmethod -->
  <testcase name="testMethod1" time="0.002" classname="Day1.assert_test"/>
  <testcase name="testMethod2" time="0.001" classname="Day1.assert_test">
    <failure type="java.lang.AssertionError" message="expected [hi] but found [Hello]">
      <![CDATA[java.lang.AssertionError: expected [hi] but found [Hello]
at Day1.assert_test.testMethod2(assert_test.java:13)
at java.util.concurrent.FutureTask.run(Unknown Source)
at java.util.concurrent.ThreadPoolExecutor.runWorker(Unknown Source)
at java.util.concurrent.ThreadPoolExecutor$Worker.run(Unknown Source)
at java.lang.Thread.run(Unknown Source)
... Removed 22 stack frames]]>
    </failure>
  </testcase> <!-- testMethod2 -->
  <testcase name="testMethod3" time="0.001" classname="Day1.assert_test"/>
</testsuite> <!-- Test -->
